Workbook

Sheet RawResultsLong
A1: raw_lookup_key | B1: scenario | C1: source_file | D1: variable_name | E1: region | F1: technology | G1: fuel | H1: emission | I1: timeslice | J1: mode | K1: storage | L1: season | M1: daytype | N1: bracket | O1: year | P1: value_pj_per_year
A2: =B2&"|"&D2&"|"&E2&"|"&F2&"|"&O2 -> PD|AccumulatedNewCapacity|RE1|PWRBGS|2022 | B2: PD | C2: simulation_328_results_filtered_PD.xlsx | D2: AccumulatedNewCapacity | E2: RE1 | F2: PWRBGS | O2: 2022
A3: =B3&"|"&D3&"|"&E3&"|"&F3&"|"&O3 -> PD|AccumulatedNewCapacity|RE1|PWRCOA|2022 | B3: PD | C3: simulation_328_results_filtered_PD.xlsx | D3: AccumulatedNewCapacity | E3: RE1 | F3: PWRCOA | O3: 2022
A4: =B4&"|"&D4&"|"&E4&"|"&F4&"|"&O4 -> PD|AccumulatedNewCapacity|RE1|PWRDSL|2022 | B4: PD | C4: simulation_328_results_filtered_PD.xlsx | D4: AccumulatedNewCapacity | E4: RE1 | F4: PWRDSL | O4: 2022
A5: =B5&"|"&D5&"|"&E5&"|"&F5&"|"&O5 -> PD|AccumulatedNewCapacity|RE1|PWRFOL|2022 | B5: PD | C5: simulation_328_results_filtered_PD.xlsx | D5: AccumulatedNewCapacity | E5: RE1 | F5: PWRFOL | O5: 2022
A6: =B6&"|"&D6&"|"&E6&"|"&F6&"|"&O6 -> PD|AccumulatedNewCapacity|RE1|PWRHYDDAM|2022 | B6: PD | C6: simulation_328_results_filtered_PD.xlsx | D6: AccumulatedNewCapacity | E6: RE1 | F6: PWRHYDDAM | O6: 2022
A7: =B7&"|"&D7&"|"&E7&"|"&F7&"|"&O7 -> PD|AccumulatedNewCapacity|RE1|PWRHYDROR|2022 | B7: PD | C7: simulation_328_results_filtered_PD.xlsx | D7: AccumulatedNewCapacity | E7: RE1 | F7: PWRHYDROR | O7: 2022
A8: =B8&"|"&D8&"|"&E8&"|"&F8&"|"&O8 -> PD|AccumulatedNewCapacity|RE1|PWRHYDROR_NDC|2022 | B8: PD | C8: simulation_328_results_filtered_PD.xlsx | D8: AccumulatedNewCapacity | E8: RE1 | F8: PWRHYDROR_NDC | O8: 2022
A9: =B9&"|"&D9&"|"&E9&"|"&F9&"|"&O9 -> PD|AccumulatedNewCapacity|RE1|PWRJET|2022 | B9: PD | C9: simulation_328_results_filtered_PD.xlsx | D9: AccumulatedNewCapacity | E9: RE1 | F9: PWRJET | O9: 2022
A10: =B10&"|"&D10&"|"&E10&"|"&F10&"|"&O10 -> PD|AccumulatedNewCapacity|RE1|PWRLPG|2022 | B10: PD | C10: simulation_328_results_filtered_PD.xlsx | D10: AccumulatedNewCapacity | E10: RE1 | F10: PWRLPG | O10: 2022
A11: =B11&"|"&D11&"|"&E11&"|"&F11&"|"&O11 -> PD|AccumulatedNewCapacity|RE1|PWRNGS_CC|2022 | B11: PD | C11: simulation_328_results_filtered_PD.xlsx | D11: AccumulatedNewCapacity | E11: RE1 | F11: PWRNGS_CC | O11: 2022
A12: =B12&"|"&D12&"|"&E12&"|"&F12&"|"&O12 -> PD|AccumulatedNewCapacity|RE1|PWRNGS_CS|2022 | B12: PD | C12: simulation_328_results_filtered_PD.xlsx | D12: AccumulatedNewCapacity | E12: RE1 | F12: PWRNGS_CS | O12: 2022
A13: =B13&"|"&D13&"|"&E13&"|"&F13&"|"&O13 -> PD|AccumulatedNewCapacity|RE1|PWRSOLRTP|2022 | B13: PD | C13: simulation_328_results_filtered_PD.xlsx | D13: AccumulatedNewCapacity | E13: RE1 | F13: PWRSOLRTP | O13: 2022
... A35: =B35&"|"&D35&"|"&E35&"|"&F35&"|"&O35 -> PD|NewCapacity|RE1|PWRWNDONS|2022 | B35: PD | C35: simulation_328_results_filtered_PD.xlsx | D35: NewCapacity | E35: RE1 | F35: PWRWNDONS | O35: 2022
A36: =B36&"|"&D36&"|"&E36&"|"&F36&"|"&O36 -> PD|TotalCapacityAnnual|RE1|PWRBGS|2022 | B36: PD | C36: simulation_328_results_filtered_PD.xlsx | D36: TotalCapacityAnnual | E36: RE1 | F36: PWRBGS | O36: 2022 | P36: 0.025488588
A37: =B37&"|"&D37&"|"&E37&"|"&F37&"|"&O37 -> PD|TotalCapacityAnnual|RE1|PWRCOA|2022 | B37: PD | C37: simulation_328_results_filtered_PD.xlsx | D37: TotalCapacityAnnual | E37: RE1 | F37: PWRCOA | O37: 2022 | P37: 51.466752
A38: =B38&"|"&D38&"|"&E38&"|"&F38&"|"&O38 -> PD|TotalCapacityAnnual|RE1|PWRDSL|2022 | B38: PD | C38: simulation_328_results_filtered_PD.xlsx | D38: TotalCapacityAnnual | E38: RE1 | F38: PWRDSL | O38: 2022 | P38: 25.954128
A39: =B39&"|"&D39&"|"&E39&"|"&F39&"|"&O39 -> PD|TotalCapacityAnnual|RE1|PWRFOL|2022 | B39: PD | C39: simulation_328_results_filtered_PD.xlsx | D39: TotalCapacityAnnual | E39: RE1 | F39: PWRFOL | O39: 2022 | P39: 8.451648
A40: =B40&"|"&D40&"|"&E40&"|"&F40&"|"&O40 -> PD|TotalCapacityAnnual|RE1|PWRHYDDAM|2022 | B40: PD | C40: simulation_328_results_filtered_PD.xlsx | D40: TotalCapacityAnnual | E40: RE1 | F40: PWRHYDDAM | O40: 2022 | P40: 345.25613
A41: =B41&"|"&D41&"|"&E41&"|"&F41&"|"&O41 -> PD|TotalCapacityAnnual|RE1|PWRHYDROR|2022 | B41: PD | C41: simulation_328_results_filtered_PD.xlsx | D41: TotalCapacityAnnual | E41: RE1 | F41: PWRHYDROR | O41: 2022 | P41: 21.160656
A42: =B42&"|"&D42&"|"&E42&"|"&F42&"|"&O42 -> PD|TotalCapacityAnnual|RE1|PWRHYDROR_NDC|2022 | B42: PD | C42: simulation_328_results_filtered_PD.xlsx | D42: TotalCapacityAnnual | E42: RE1 | F42: PWRHYDROR_NDC | O42: 2022 | P42: 28.102581
A43: =B43&"|"&D43&"|"&E43&"|"&F43&"|"&O43 -> PD|TotalCapacityAnnual|RE1|PWRJET|2022 | B43: PD | C43: simulation_328_results_filtered_PD.xlsx | D43: TotalCapacityAnnual | E43: RE1 | F43: PWRJET | O43: 2022 | P43: 1.608336
A44: =B44&"|"&D44&"|"&E44&"|"&F44&"|"&O44 -> PD|TotalCapacityAnnual|RE1|PWRLPG|2022 | B44: PD | C44: simulation_328_results_filtered_PD.xlsx | D44: TotalCapacityAnnual | E44: RE1 | F44: PWRLPG | O44: 2022
A45: =B45&"|"&D45&"|"&E45&"|"&F45&"|"&O45 -> PD|TotalCapacityAnnual|RE1|PWRNGS_CC|2022 | B45: PD | C45: simulation_328_results_filtered_PD.xlsx | D45: TotalCapacityAnnual | E45: RE1 | F45: PWRNGS_CC | O45: 2022 | P45: 62.5044
A46: =B46&"|"&D46&"|"&E46&"|"&F46&"|"&O46 -> PD|TotalCapacityAnnual|RE1|PWRNGS_CS|2022 | B46: PD | C46: simulation_328_results_filtered_PD.xlsx | D46: TotalCapacityAnnual | E46: RE1 | F46: PWRNGS_CS | O46: 2022 | P46: 23.96736
A47: =B47&"|"&D47&"|"&E47&"|"&F47&"|"&O47 -> PD|TotalCapacityAnnual|RE1|PWRSOLRTP|2022 | B47: PD | C47: simulation_328_results_filtered_PD.xlsx | D47: TotalCapacityAnnual | E47: RE1 | F47: PWRSOLRTP | O47: 2022 | P47: 3.9230228
A48: =B48&"|"&D48&"|"&E48&"|"&F48&"|"&O48 -> PD|TotalCapacityAnnual|RE1|PWRSOLRTP_ZNI|2022 | B48: PD | C48: simulation_328_results_filtered_PD.xlsx | D48: TotalCapacityAnnual | E48: RE1 | F48: PWRSOLRTP_ZNI | O48: 2022 | P48: 0.46074096
A49: =B49&"|"&D49&"|"&E49&"|"&F49&"|"&O49 -> PD|TotalCapacityAnnual|RE1|PWRSOLUGE|2022 | B49: PD | C49: simulation_328_results_filtered_PD.xlsx | D49: TotalCapacityAnnual | E49: RE1 | F49: PWRSOLUGE | O49: 2022 | P49: 6.874848
A50: =B50&"|"&D50&"|"&E50&"|"&F50&"|"&O50 -> PD|TotalCapacityAnnual|RE1|PWRSOLUPE|2022 | B50: PD | C50: simulation_328_results_filtered_PD.xlsx | D50: TotalCapacityAnnual | E50: RE1 | F50: PWRSOLUPE | O50: 2022 | P50: 7.9224739
A51: =B51&"|"&D51&"|"&E51&"|"&F51&"|"&O51 -> PD|TotalCapacityAnnual|RE1|PWRSTD|2022 | B51: PD | C51: simulation_328_results_filtered_PD.xlsx | D51: TotalCapacityAnnual | E51: RE1 | F51: PWRSTD | O51: 2022 | P51: 8.1630621
A52: =B52&"|"&D52&"|"&E52&"|"&F52&"|"&O52 -> PD|TotalCapacityAnnual|RE1|PWRWNDONS|2022 | B52: PD | C52: simulation_328_results_filtered_PD.xlsx | D52: TotalCapacityAnnual | E52: RE1 | F52: PWRWNDONS | O52: 2022 | P52: 1.2116131
A53: =B53&"|"&D53&"|"&E53&"|"&F53&"|"&O53 -> PD|AccumulatedNewCapacity|RE1|PWRBGS|2023 | B53: PD | C53: simulation_328_results_filtered_PD.xlsx | D53: AccumulatedNewCapacity | E53: RE1 | F53: PWRBGS | O53: 2023
A54: =B54&"|"&D54&"|"&E54&"|"&F54&"|"&O54 -> PD|AccumulatedNewCapacity|RE1|PWRCOA|2023 | B54: PD | C54: simulation_328_results_filtered_PD.xlsx | D54: AccumulatedNewCapacity | E54: RE1 | F54: PWRCOA | O54: 2023
A55: =B55&"|"&D55&"|"&E55&"|"&F55&"|"&O55 -> PD|AccumulatedNewCapacity|RE1|PWRDSL|2023 | B55: PD | C55: simulation_328_results_filtered_PD.xlsx | D55: AccumulatedNewCapacity | E55: RE1 | F55: PWRDSL | O55: 2023
A56: =B56&"|"&D56&"|"&E56&"|"&F56&"|"&O56 -> PD|AccumulatedNewCapacity|RE1|PWRFOL|2023 | B56: PD | C56: simulation_328_results_filtered_PD.xlsx | D56: AccumulatedNewCapacity | E56: RE1 | F56: PWRFOL | O56: 2023
A57: =B57&"|"&D57&"|"&E57&"|"&F57&"|"&O57 -> PD|AccumulatedNewCapacity|RE1|PWRHYDDAM|2023 | B57: PD | C57: simulation_328_results_filtered_PD.xlsx | D57: AccumulatedNewCapacity | E57: RE1 | F57: PWRHYDDAM | O57: 2023
A58: =B58&"|"&D58&"|"&E58&"|"&F58&"|"&O58 -> PD|AccumulatedNewCapacity|RE1|PWRHYDROR|2023 | B58: PD | C58: simulation_328_results_filtered_PD.xlsx | D58: AccumulatedNewCapacity | E58: RE1 | F58: PWRHYDROR | O58: 2023
A59: =B59&"|"&D59&"|"&E59&"|"&F59&"|"&O59 -> PD|AccumulatedNewCapacity|RE1|PWRHYDROR_NDC|2023 | B59: PD | C59: simulation_328_results_filtered_PD.xlsx | D59: AccumulatedNewCapacity | E59: RE1 | F59: PWRHYDROR_NDC | O59: 2023
A60: =B60&"|"&D60&"|"&E60&"|"&F60&"|"&O60 -> PD|AccumulatedNewCapacity|RE1|PWRJET|2023 | B60: PD | C60: simulation_328_results_filtered_PD.xlsx | D60: AccumulatedNewCapacity | E60: RE1 | F60: PWRJET | O60: 2023
A61: =B61&"|"&D61&"|"&E61&"|"&F61&"|"&O61 -> PD|AccumulatedNewCapacity|RE1|PWRLPG|2023 | B61: PD | C61: simulation_328_results_filtered_PD.xlsx | D61: AccumulatedNewCapacity | E61: RE1 | F61: PWRLPG | O61: 2023
...

Sheet FactorInputs
A1: factor_lookup_key | B1: Source | C1: Technology | D1: Factor_Type | E1: Job_Type | F1: Unit | G1: Year | H1: Value | I1: Value_Numeric | J1: Method_Applied | K1: Mapped_Rutovitz_Tech | L1: Rutovitz_2030_Factor | M1: Mapped_Catalogue_Tech | N1: Learning_Rate | O1: Projection_Input | P1: Base_Year | Q1: Projected_Year | R1: Projected_Value | S1: Interpolation_Method | T1: Default_Source | U1: Default_Source_Note
A2: =C2&"|"&G2&"|"&D2&"|"&E2 -> Battery storage (grid)|2047|Construction&Manufacturing|Direct | B2: Rutovitz 2025 | C2: Battery storage (grid) | D2: Construction&Manufacturing | E2: Direct | F2: job-yr/MW | G2: 2047 | H2: 0.38457119 | I2: 0.38457119 | J2: Linear interpolation | M2: Utility-scale Lithium-ion | O2: Construction + Manufacturing; Rutovitz 2025 total manufacturing factor used without local-share scaling | P2: 2030 | Q2: 2047 | R2: 0.38457119 | S2: Linear interpolation between known datapoints | T2: Rutovitz 2025
A3: =C3&"|"&G3&"|"&D3&"|"&E3 -> Battery storage (grid)|2047|O&M|Direct | B3: Rutovitz 2025 | C3: Battery storage (grid) | D3: O&M | E3: Direct | F3: job/MW | G3: 2047 | H3: 0.017994675 | I3: 0.017994675 | J3: Linear interpolation | M3: Utility-scale Lithium-ion | O3: OPEX 2050/2030=0.8009507801593532 | P3: 2030 | Q3: 2047 | R3: 0.017994675 | S3: Linear interpolation between known datapoints | T3: Rutovitz 2025
A4: =C4&"|"&G4&"|"&D4&"|"&E4 -> Battery storage (grid)|2048|O&M|Direct | B4: Rutovitz 2025 | C4: Battery storage (grid) | D4: O&M | E4: Direct | F4: job/MW | G4: 2048 | H4: 0.017779113 | I4: 0.017779113 | J4: Linear interpolation | M4: Utility-scale Lithium-ion | O4: OPEX 2050/2030=0.8009507801593532 | P4: 2030 | Q4: 2048 | R4: 0.017779113 | S4: Linear interpolation between known datapoints | T4: Rutovitz 2025
A5: =C5&"|"&G5&"|"&D5&"|"&E5 -> Battery storage (grid)|2049|O&M|Direct | B5: Rutovitz 2025 | C5: Battery storage (grid) | D5: O&M | E5: Direct | F5: job/MW | G5: 2049 | H5: 0.01756355 | I5: 0.01756355 | J5: Linear interpolation | M5: Utility-scale Lithium-ion | O5: OPEX 2050/2030=0.8009507801593532 | P5: 2030 | Q5: 2049 | R5: 0.01756355 | S5: Linear interpolation between known datapoints | T5: Rutovitz 2025
A6: =C6&"|"&G6&"|"&D6&"|"&E6 -> Battery storage (grid)|2050|O&M|Direct | B6: Rutovitz 2025 | C6: Battery storage (grid) | D6: O&M | E6: Direct | F6: job/MW | G6: 2050 | H6: 0.017347987 | I6: 0.017347987 | J6: CAPEX/OPEX ratio projection | M6: Utility-scale Lithium-ion | O6: OPEX 2050/2030=0.8009507801593532 | P6: 2030 | Q6: 2050 | R6: 0.017347987 | S6: Known datapoint | T6: Rutovitz 2025
A7: =C7&"|"&G7&"|"&D7&"|"&E7 -> Battery storage (grid)|2051|O&M|Direct | B7: Rutovitz 2025 | C7: Battery storage (grid) | D7: O&M | E7: Direct | F7: job/MW | G7: 2051 | H7: 0.017347987 | I7: 0.017347987 | J7: Linear interpolation | M7: Utility-scale Lithium-ion | O7: OPEX 2050/2030=0.8009507801593532 | P7: 2030 | Q7: 2051 | R7: 0.017347987 | S7: Linear interpolation to 2050; held constant after 2050 | T7: Rutovitz 2025
A8: =C8&"|"&G8&"|"&D8&"|"&E8 -> Battery storage (grid)|2052|O&M|Direct | B8: Rutovitz 2025 | C8: Battery storage (grid) | D8: O&M | E8: Direct | F8: job/MW | G8: 2052 | H8: 0.017347987 | I8: 0.017347987 | J8: Linear interpolation | M8: Utility-scale Lithium-ion | O8: OPEX 2050/2030=0.8009507801593532 | P8: 2030 | Q8: 2052 | R8: 0.017347987 | S8: Linear interpolation to 2050; held constant after 2050 | T8: Rutovitz 2025
A9: =C9&"|"&G9&"|"&D9&"|"&E9 -> Battery storage (grid)|2053|O&M|Direct | B9: Rutovitz 2025 | C9: Battery storage (grid) | D9: O&M | E9: Direct | F9: job/MW | G9: 2053 | H9: 0.017347987 | I9: 0.017347987 | J9: Linear interpolation | M9: Utility-scale Lithium-ion | O9: OPEX 2050/2030=0.8009507801593532 | P9: 2030 | Q9: 2053 | R9: 0.017347987 | S9: Linear interpolation to 2050; held constant after 2050 | T9: Rutovitz 2025
A10: =C10&"|"&G10&"|"&D10&"|"&E10 -> Battery storage (grid)|2054|O&M|Direct | B10: Rutovitz 2025 | C10: Battery storage (grid) | D10: O&M | E10: Direct | F10: job/MW | G10: 2054 | H10: 0.017347987 | I10: 0.017347987 | J10: Linear interpolation | M10: Utility-scale Lithium-ion | O10: OPEX 2050/2030=0.8009507801593532 | P10: 2030 | Q10: 2054 | R10: 0.017347987 | S10: Linear interpolation to 2050; held constant after 2050 | T10: Rutovitz 2025
A11: =C11&"|"&G11&"|"&D11&"|"&E11 -> Battery storage (grid)|2055|O&M|Direct | B11: Rutovitz 2025 | C11: Battery storage (grid) | D11: O&M | E11: Direct | F11: job/MW | G11: 2055 | H11: 0.017347987 | I11: 0.017347987 | J11: Linear interpolation | M11: Utility-scale Lithium-ion | O11: OPEX 2050/2030=0.8009507801593532 | P11: 2030 | Q11: 2055 | R11: 0.017347987 | S11: Linear interpolation to 2050; held constant after 2050 | T11: Rutovitz 2025
A12: =C12&"|"&G12&"|"&D12&"|"&E12 -> Geothermal|2040|Construction&Manufacturing|Direct | B12: I-JEDI | C12: Geothermal | D12: Construction&Manufacturing | E12: Direct | F12: job-yr/MW | G12: 2040 | H12: 4.6071987 | I12: 4.6071987 | J12: Linear interpolation | M12: Geothermal large | O12: CAPEX 2050/2030=0.9229247031680952 | P12: 2030 | Q12: 2040 | R12: 4.6071987 | S12: Linear interpolation between known datapoints | T12: I-JEDI
A13: =C13&"|"&G13&"|"&D13&"|"&E13 -> Geothermal|2041|Construction&Manufacturing|Direct | B13: I-JEDI | C13: Geothermal | D13: Construction&Manufacturing | E13: Direct | F13: job-yr/MW | G13: 2041 | H13: 4.588732 | I13: 4.588732 | J13: Linear interpolation | M13: Geothermal large | O13: CAPEX 2050/2030=0.9229247031680952 | P13: 2030 | Q13: 2041 | R13: 4.588732 | S13: Linear interpolation between known datapoints | T13: I-JEDI
... A37: =C37&"|"&G37&"|"&D37&"|"&E37 -> Geothermal|2055|O&M|Direct | B37: I-JEDI | C37: Geothermal | D37: O&M | E37: Direct | F37: job/MW | G37: 2055 | H37: 0.0069576837 | I37: 0.0069576837 | J37: Linear interpolation | M37: Geothermal large | O37: OPEX 2050/2030=0.9231678486997636 | P37: 2030 | Q37: 2055 | R37: 0.0069576837 | S37: Linear interpolation to 2050; held constant after 2050 | T37: I-JEDI
A38: =C38&"|"&G38&"|"&D38&"|"&E38 -> Hydro (large)|2028|Construction&Manufacturing|Direct | B38: Rutovitz 2015 | C38: Hydro (large) | D38: Construction&Manufacturing | E38: Direct | F38: job-yr/MW | G38: 2028 | H38: 11.561267 | I38: 11.561267 | J38: Linear interpolation | K38: Hydro-large | M38: Large Hydro reservoir | O38: Construction + Manufacturing; full regional manufacturing assumed by Rutovitz 2015 method | P38: 2030 | Q38: 2028 | R38: 11.561267 | S38: Linear interpolation between known datapoints | T38: Rutovitz 2015
A39: =C39&"|"&G39&"|"&D39&"|"&E39 -> Hydro (large)|2028|O&M|Direct | B39: Rutovitz 2015 | C39: Hydro (large) | D39: O&M | E39: Direct | F39: job/MW | G39: 2028 | H39: 0.6364 | I39: 0.6364 | J39: Linear interpolation | K39: Hydro-large | M39: Large Hydro reservoir | O39: OPEX 2050/2030=0.994535519125683 | P39: 2030 | Q39: 2028 | R39: 0.6364 | S39: Linear interpolation between known datapoints | T39: Rutovitz 2015
A40: =C40&"|"&G40&"|"&D40&"|"&E40 -> Hydro (large)|2029|O&M|Direct | B40: Rutovitz 2015 | C40: Hydro (large) | D40: O&M | E40: Direct | F40: job/MW | G40: 2029 | H40: 0.6392 | I40: 0.6392 | J40: Linear interpolation | K40: Hydro-large | M40: Large Hydro reservoir | O40: OPEX 2050/2030=0.994535519125683 | P40: 2030 | Q40: 2029 | R40: 0.6392 | S40: Linear interpolation between known datapoints | T40: Rutovitz 2015
A41: =C41&"|"&G41&"|"&D41&"|"&E41 -> Hydro (large)|2030|O&M|Direct | B41: Rutovitz 2015 | C41: Hydro (large) | D41: O&M | E41: Direct | F41: job/MW | G41: 2030 | H41: 0.642 | I41: 0.642 | J41: Rutovitz Table 9 decline to 2030 | K41: Hydro-large | L41: 1.07 | O41: Rutovitz Table 9 Latin America 2030 | P41: 2015 | Q41: 2030 | R41: 0.642 | S41: Known datapoint | T41: Rutovitz 2015
A42: =C42&"|"&G42&"|"&D42&"|"&E42 -> Hydro (large)|2031|O&M|Direct | B42: Rutovitz 2015 | C42: Hydro (large) | D42: O&M | E42: Direct | F42: job/MW | G42: 2031 | H42: 0.64182459 | I42: 0.64182459 | J42: Linear interpolation | K42: Hydro-large | M42: Large Hydro reservoir | O42: OPEX 2050/2030=0.994535519125683 | P42: 2030 | Q42: 2031 | R42: 0.64182459 | S42: Linear interpolation between known datapoints | T42: Rutovitz 2015
A43: =C43&"|"&G43&"|"&D43&"|"&E43 -> Hydro (large)|2032|O&M|Direct | B43: Rutovitz 2015 | C43: Hydro (large) | D43: O&M | E43: Direct | F43: job/MW | G43: 2032 | H43: 0.64164918 | I43: 0.64164918 | J43: Linear interpolation | K43: Hydro-large | M43: Large Hydro reservoir | O43: OPEX 2050/2030=0.994535519125683 | P43: 2030 | Q43: 2032 | R43: 0.64164918 | S43: Linear interpolation between known datapoints | T43: Rutovitz 2015
A44: =C44&"|"&G44&"|"&D44&"|"&E44 -> Hydro (large)|2033|O&M|Direct | B44: Rutovitz 2015 | C44: Hydro (large) | D44: O&M | E44: Direct | F44: job/MW | G44: 2033 | H44: 0.64147377 | I44: 0.64147377 | J44: Linear interpolation | K44: Hydro-large | M44: Large Hydro reservoir | O44: OPEX 2050/2030=0.994535519125683 | P44: 2030 | Q44: 2033 | R44: 0.64147377 | S44: Linear interpolation between known datapoints | T44: Rutovitz 2015
A45: =C45&"|"&G45&"|"&D45&"|"&E45 -> Hydro (large)|2034|O&M|Direct | B45: Rutovitz 2015 | C45: Hydro (large) | D45: O&M | E45: Direct | F45: job/MW | G45: 2034 | H45: 0.64129836 | I45: 0.64129836 | J45: Linear interpolation | K45: Hydro-large | M45: Large Hydro reservoir | O45: OPEX 2050/2030=0.994535519125683 | P45: 2030 | Q45: 2034 | R45: 0.64129836 | S45: Linear interpolation between known datapoints | T45: Rutovitz 2015
A46: =C46&"|"&G46&"|"&D46&"|"&E46 -> Hydro (large)|2035|O&M|Direct | B46: Rutovitz 2015 | C46: Hydro (large) | D46: O&M | E46: Direct | F46: job/MW | G46: 2035 | H46: 0.64112295 | I46: 0.64112295 | J46: Linear interpolation | K46: Hydro-large | M46: Large Hydro reservoir | O46: OPEX 2050/2030=0.994535519125683 | P46: 2030 | Q46: 2035 | R46: 0.64112295 | S46: Linear interpolation between known datapoints | T46: Rutovitz 2015
A47: =C47&"|"&G47&"|"&D47&"|"&E47 -> Hydro (large)|2036|O&M|Direct | B47: Rutovitz 2015 | C47: Hydro (large) | D47: O&M | E47: Direct | F47: job/MW | G47: 2036 | H47: 0.64094754 | I47: 0.64094754 | J47: Linear interpolation | K47: Hydro-large | M47: Large Hydro reservoir | O47: OPEX 2050/2030=0.994535519125683 | P47: 2030 | Q47: 2036 | R47: 0.64094754 | S47: Linear interpolation between known datapoints | T47: Rutovitz 2015
A48: =C48&"|"&G48&"|"&D48&"|"&E48 -> Hydro (large)|2037|O&M|Direct | B48: Rutovitz 2015 | C48: Hydro (large) | D48: O&M | E48: Direct | F48: job/MW | G48: 2037 | H48: 0.64077213 | I48: 0.64077213 | J48: Linear interpolation | K48: Hydro-large | M48: Large Hydro reservoir | O48: OPEX 2050/2030=0.994535519125683 | P48: 2030 | Q48: 2037 | R48: 0.64077213 | S48: Linear interpolation between known datapoints | T48: Rutovitz 2015
A49: =C49&"|"&G49&"|"&D49&"|"&E49 -> Hydro (large)|2038|O&M|Direct | B49: Rutovitz 2015 | C49: Hydro (large) | D49: O&M | E49: Direct | F49: job/MW | G49: 2038 | H49: 0.64059672 | I49: 0.64059672 | J49: Linear interpolation | K49: Hydro-large | M49: Large Hydro reservoir | O49: OPEX 2050/2030=0.994535519125683 | P49: 2030 | Q49: 2038 | R49: 0.64059672 | S49: Linear interpolation between known datapoints | T49: Rutovitz 2015
A50: =C50&"|"&G50&"|"&D50&"|"&E50 -> Hydro (large)|2039|O&M|Direct | B50: Rutovitz 2015 | C50: Hydro (large) | D50: O&M | E50: Direct | F50: job/MW | G50: 2039 | H50: 0.64042131 | I50: 0.64042131 | J50: Linear interpolation | K50: Hydro-large | M50: Large Hydro reservoir | O50: OPEX 2050/2030=0.994535519125683 | P50: 2030 | Q50: 2039 | R50: 0.64042131 | S50: Linear interpolation between known datapoints | T50: Rutovitz 2015
A51: =C51&"|"&G51&"|"&D51&"|"&E51 -> Hydro (large)|2040|O&M|Direct | B51: Rutovitz 2015 | C51: Hydro (large) | D51: O&M | E51: Direct | F51: job/MW | G51: 2040 | H51: 0.6402459 | I51: 0.6402459 | J51: Linear interpolation | K51: Hydro-large | M51: Large Hydro reservoir | O51: OPEX 2050/2030=0.994535519125683 | P51: 2030 | Q51: 2040 | R51: 0.6402459 | S51: Linear interpolation between known datapoints | T51: Rutovitz 2015
A52: =C52&"|"&G52&"|"&D52&"|"&E52 -> Hydro (large)|2041|O&M|Direct | B52: Rutovitz 2015 | C52: Hydro (large) | D52: O&M | E52: Direct | F52: job/MW | G52: 2041 | H52: 0.64007049 | I52: 0.64007049 | J52: Linear interpolation | K52: Hydro-large | M52: Large Hydro reservoir | O52: OPEX 2050/2030=0.994535519125683 | P52: 2030 | Q52: 2041 | R52: 0.64007049 | S52: Linear interpolation between known datapoints | T52: Rutovitz 2015
A53: =C53&"|"&G53&"|"&D53&"|"&E53 -> Hydro (large)|2042|O&M|Direct | B53: Rutovitz 2015 | C53: Hydro (large) | D53: O&M | E53: Direct | F53: job/MW | G53: 2042 | H53: 0.63989508 | I53: 0.63989508 | J53: Linear interpolation | K53: Hydro-large | M53: Large Hydro reservoir | O53: OPEX 2050/2030=0.994535519125683 | P53: 2030 | Q53: 2042 | R53: 0.63989508 | S53: Linear interpolation between known datapoints | T53: Rutovitz 2015
... A105: =C105&"|"&G105&"|"&D105&"|"&E105 -> Nuclear|2055|O&M|Direct | B105: Rutovitz 2015 | C105: Nuclear | D105: O&M | E105: Direct | F105: job/MW | G105: 2055 | H105: 1.0829167 | I105: 1.0829167 | J105: Linear interpolation | K105: Nuclear | M105: Nuclear PWR | O105: OPEX 2050/2030=0.9416666666666668 | P105: 2030 | Q105: 2055 | R105: 1.0829167 | S105: Linear interpolation to 2050; held constant after 2050 | T105: Rutovitz 2015
A106: =C106&"|"&G106&"|"&D106&"|"&E106 -> Offshore wind (fixed)|2032|Construction&Manufacturing|Direct | B106: French QBIS 2023 | C106: Offshore wind (fixed) | D106: Construction&Manufacturing | E106: Direct | F106: job-yr/MW | G106: 2032 | H106: 4.6353844 | I106: 4.6353844 | J106: Linear interpolation | M106: Wind Offshore fixed bottom | O106: CAPEX 2050/2030=0.7005449997448997 | P106: 2030 | Q106: 2032 | R106: 4.6353844 | S106: Linear interpolation between known datapoints | T106: French QBIS 2023
A107: =C107&"|"&G107&"|"&D107&"|"&E107 -> Offshore wind (fixed)|2033|Construction&Manufacturing|Direct | B107: French QBIS 2023 | C107: Offshore wind (fixed) | D107: Construction&Manufacturing | E107: Direct | F107: job-yr/MW | G107: 2033 | H107: 4.5638374 | I107: 4.5638374 | J107: Linear interpolation | M107: Wind Offshore fixed bottom | O107: CAPEX 2050/2030=0.7005449997448997 | P107: 2030 | Q107: 2033 | R107: 4.5638374 | S107: Linear interpolation between known datapoints | T107: French QBIS 2023
A108: =C108&"|"&G108&"|"&D108&"|"&E108 -> Offshore wind (fixed)|2034|Construction&Manufacturing|Direct | B108: French QBIS 2023 | C108: Offshore wind (fixed) | D108: Construction&Manufacturing | E108: Direct | F108: job-yr/MW | G108: 2034 | H108: 4.4922905 | I108: 4.4922905 | J108: Linear interpolation | M108: Wind Offshore fixed bottom | O108: CAPEX 2050/2030=0.7005449997448997 | P108: 2030 | Q108: 2034 | R108: 4.4922905 | S108: Linear interpolation between known datapoints | T108: French QBIS 2023
A109: =C109&"|"&G109&"|"&D109&"|"&E109 -> Offshore wind (fixed)|2035|Construction&Manufacturing|Direct | B109: French QBIS 2023 | C109: Offshore wind (fixed) | D109: Construction&Manufacturing | E109: Direct | F109: job-yr/MW | G109: 2035 | H109: 4.4207435 | I109: 4.4207435 | J109: Linear interpolation | M109: Wind Offshore fixed bottom | O109: CAPEX 2050/2030=0.7005449997448997 | P109: 2030 | Q109: 2035 | R109: 4.4207435 | S109: Linear interpolation between known datapoints | T109: French QBIS 2023
A110: =C110&"|"&G110&"|"&D110&"|"&E110 -> Offshore wind (fixed)|2036|Construction&Manufacturing|Direct | B110: French QBIS 2023 | C110: Offshore wind (fixed) | D110: Construction&Manufacturing | E110: Direct | F110: job-yr/MW | G110: 2036 | H110: 4.3491966 | I110: 4.3491966 | J110: Linear interpolation | M110: Wind Offshore fixed bottom | O110: CAPEX 2050/2030=0.7005449997448997 | P110: 2030 | Q110: 2036 | R110: 4.3491966 | S110: Linear interpolation between known datapoints | T110: French QBIS 2023
A111: =C111&"|"&G111&"|"&D111&"|"&E111 -> Offshore wind (fixed)|2037|Construction&Manufacturing|Direct | B111: French QBIS 2023 | C111: Offshore wind (fixed) | D111: Construction&Manufacturing | E111: Direct | F111: job-yr/MW | G111: 2037 | H111: 4.2776496 | I111: 4.2776496 | J111: Linear interpolation | M111: Wind Offshore fixed bottom | O111: CAPEX 2050/2030=0.7005449997448997 | P111: 2030 | Q111: 2037 | R111: 4.2776496 | S111: Linear interpolation between known datapoints | T111: French QBIS 2023
A112: =C112&"|"&G112&"|"&D112&"|"&E112 -> Offshore wind (fixed)|2038|Construction&Manufacturing|Direct | B112: French QBIS 2023 | C112: Offshore wind (fixed) | D112: Construction&Manufacturing | E112: Direct | F112: job-yr/MW | G112: 2038 | H112: 4.2061026 | I112: 4.2061026 | J112: Linear interpolation | M112: Wind Offshore fixed bottom | O112: CAPEX 2050/2030=0.7005449997448997 | P112: 2030 | Q112: 2038 | R112: 4.2061026 | S112: Linear interpolation between known datapoints | T112: French QBIS 2023
A113: =C113&"|"&G113&"|"&D113&"|"&E113 -> Offshore wind (fixed)|2039|Construction&Manufacturing|Direct | B113: French QBIS 2023 | C113: Offshore wind (fixed) | D113: Construction&Manufacturing | E113: Direct | F113: job-yr/MW | G113: 2039 | H113: 4.1345557 | I113: 4.1345557 | J113: Linear interpolation | M113: Wind Offshore fixed bottom | O113: CAPEX 2050/2030=0.7005449997448997 | P113: 2030 | Q113: 2039 | R113: 4.1345557 | S113: Linear interpolation between known datapoints | T113: French QBIS 2023
A114: =C114&"|"&G114&"|"&D114&"|"&E114 -> Offshore wind (fixed)|2040|Construction&Manufacturing|Direct | B114: French QBIS 2023 | C114: Offshore wind (fixed) | D114: Construction&Manufacturing | E114: Direct | F114: job-yr/MW | G114: 2040 | H114: 4.0630087 | I114: 4.0630087 | J114: Linear interpolation | M114: Wind Offshore fixed bottom | O114: CAPEX 2050/2030=0.7005449997448997 | P114: 2030 | Q114: 2040 | R114: 4.0630087 | S114: Linear interpolation between known datapoints | T114: French QBIS 2023
...

Sheet Pivot_EmploymentFTE
A1: scenario | B1: CN
A2: factor_type | B2: Construction&Manufacturing
A4: Sum of employment_fte | B4: Column Labels
A5: Row Labels | B5: PWRHYDDAM | C5: PWRHYDROR_NDC | D5: PWRSOLRTP | E5: PWRSOLRTP_ZNI | F5: PWRSOLUGE | G5: PWRSOLUGE_BAT | H5: PWRSOLUPE | I5: PWRWNDOFS_FIX | J5: PWRWNDOFS_FLO | K5: PWRWNDONS | L5: Grand Total
A6: 2025 | F6: 2012.5688 | H6: 1591.1577 | K6: 34.978894 | L6: 3638.7053
A7: 2026 | D7: 2748.2612 | F7: 15804.571 | H7: 953.18804 | K7: 3191.0442 | L7: 22697.064
A8: 2027 | D8: 3706.1016 | F8: 19491.576 | H8: 926.16561 | K8: 3893.9582 | L8: 28017.802
A9: 2028 | B9: 13862.852 | D9: 3828.6379 | K9: 1419.7744 | L9: 19111.264
A10: 2029 | D10: 3905.6306 | K10: 2088.9435 | L10: 5994.5741
A11: 2030 | D11: 3690.3752 | F11: 1719.0497 | K11: 2048.6156 | L11: 7458.0405
A12: 2031 | D12: 3535.5068 | E12: 114.91186 | K12: 2043.182 | L12: 5693.6007
A13: 2032 | D13: 3113.6356 | E13: 7.6484736 | K13: 2037.7484 | L13: 5159.0325
A14: 2033 | D14: 3085.956 | E14: 7.5794707 | K14: 2032.3147 | L14: 5125.8502
A15: 2034 | D15: 2543.0758 | E15: 7.493912 | K15: 2026.8811 | L15: 4577.4508
A16: 2035 | D16: 2206.424 | E16: 7.4268769 | K16: 10173.902 | L16: 12387.753
A17: 2036 | D17: 2201.8615 | E17: 7.4304026 | I17: 1799.0678 | K17: 10146.555 | L17: 14154.915
A18: 2037 | D18: 1831.5258 | E18: 7.4236419 | I18: 3135.3925 | K18: 10119.207 | L18: 15093.549
A19: 2038 | D19: 1363.6469 | E19: 7.4237706 | I19: 6305.6353 | K19: 10091.86 | L19: 17768.566
A20: 2039 | D20: 1045.9637 | E20: 7.421738 | F20: 8792.5796 | I20: 6198.3747 | K20: 10064.513 | L20: 26108.852
A21: 2040 | C21: 28299.81 | D21: 836.66019 | E21: 7.418956 | F21: 8623.3543 | I21: 6091.1141 | K21: 10037.165 | L21: 53895.523
A22: 2041 | C22: 24958.108 | D22: 688.24738 | E22: 7.4159775 | F22: 8454.1291 | I22: 5983.8535 | K22: 10009.818 | L22: 50101.572
A23: 2042 | D23: 751.95524 | E23: 7.4044245 | F23: 8284.9039 | I23: 5876.5929 | K23: 9982.4706 | L23: 24903.327
A24: 2043 | D24: 487.47176 | E24: 7.3888238 | F24: 591.3334 | I24: 5769.3323 | K24: 9955.1232 | L24: 16810.65
A25: 2044 | D25: 438.04022 | E25: 7.3644227 | F25: 1250.7012 | I25: 1067.8179 | K25: 9927.7758 | L25: 12691.7
A26: 2045 | D26: 404.11205 | E26: 8.6689239 | F26: 6142.305 | I26: 5554.8112 | K26: 9900.4285 | L26: 22010.326
A27: 2046 | D27: 381.77694 | E27: 7.1728938 | F27: 7608.003 | I27: 5447.5506 | K27: 9873.0811 | L27: 23317.585
A28: 2047 | C28: 28249.272 | D28: 373.27076 | E28: 6.1475267 | F28: 7438.7778 | G28: 5046.6605 | I28: 5340.29 | J28: 632.62434 | K28: 9845.7338 | L28: 56932.777
A29: 2048 | C29: 28242.053 | D29: 182.38229 | E29: 8.1074245 | F29: 7269.5526 | I29: 5233.0294 | J29: 1295.7414 | K29: 9818.3864 | L29: 52049.252
A30: 2049 | D30: 178.1292 | E30: 6.3008047 | I30: 3861.7467 | K30: 9791.039 | L30: 13837.216
A31: 2050 | D31: 173.8761 | L31: 173.8761
A32: 2051 | D32: 173.8761 | K32: 9763.6917 | L32: 9937.5678
A33: 2052 | D33: 173.8761 | F33: 6931.1022 | I33: 1241.813 | K33: 9763.6917 | L33: 18110.483
A34: 2053 | D34: 173.8761 | E34: 3.0209519 | F34: 6595.998 | I34: 2374.91 | K34: 9763.6917 | L34: 18911.497
A35: 2054 | D35: 173.8761 | E35: 3.0861022 | F35: 1522.9253 | I35: 2245.7811 | K35: 9763.6917 | L35: 13709.36
A36: 2055 | D36: 173.8761 | K36: 2360.7773 | L36: 2534.6535
A37: Grand Total | B37: 13862.852 | C37: 109749.24 | D37: 44571.905 | E37: 254.25738 | F37: 118533.43 | G37: 5046.6605 | H37: 3470.5113 | I37: 73527.113 | J37: 1928.3657 | K37: 211970.04 | L37: 582914.38

Sheet Pivot_CapacityMW
A1: scenario | B1: CN
A2: variable_name | B2: NewCapacity
A4: Sum of capacity_mw | B4: Column Labels
A5: Row Labels | B5: PWRHYDDAM | C5: PWRHYDROR_NDC | D5: PWRSOLRTP | E5: PWRSOLRTP_ZNI | F5: PWRSOLUGE | G5: PWRSOLUGE_BAT | H5: PWRSOLUPE | I5: PWRWNDOFS_FIX | J5: PWRWNDOFS_FLO | K5: PWRWNDONS | L5: Grand Total
A6: 2025 | F6: 212.85421 | H6: 168.28474 | K6: 4.8680291 | L6: 386.00698
A7: 2026 | D7: 328.60547 | F7: 1767.7892 | H7: 106.61697 | K7: 447.93721 | L7: 2650.9488
A8: 2027 | D8: 470.25122 | F8: 2313.4155 | H8: 109.92471 | K8: 551.37273 | L8: 3444.9641
A9: 2028 | B9: 1199.0772 | D9: 517.46647 | K9: 202.80376 | L9: 1919.3475
A10: 2029 | D10: 564.68172 | K10: 301.03683 | L10: 865.71856
A11: 2030 | D11: 573.55439 | F11: 249.82888 | K11: 297.86803 | L11: 1121.2513
A12: 2031 | D12: 558.66099 | E12: 18.157728 | K12: 297.86803 | L12: 874.68674
A13: 2032 | D13: 500.35491 | E13: 1.2290941 | K13: 297.86803 | L13: 799.45203
A14: 2033 | D14: 504.47436 | E14: 1.2390483 | K14: 297.86803 | L14: 803.58143
A15: 2034 | D15: 423.03597 | E15: 1.2465985 | K15: 297.86803 | L15: 722.1506
A16: 2035 | D16: 373.60256 | E16: 1.2575553 | K16: 1499.1634 | L16: 1874.0235
A17: 2036 | D17: 379.62329 | E17: 1.2810769 | I17: 413.65521 | K17: 1499.1634 | L17: 2293.723
A18: 2037 | D18: 321.63409 | E18: 1.3036651 | I18: 732.97085 | K18: 1499.1634 | L18: 2555.072
A19: 2038 | D19: 243.99828 | E19: 1.3283403 | I19: 1499.1634 | K19: 1499.1634 | L19: 3243.6535
A20: 2039 | D20: 190.76229 | E20: 1.3535726 | F20: 1499.1634 | I20: 1499.1634 | K20: 1499.1634 | L20: 4689.6062
A21: 2040 | C21: 993.10467 | D21: 155.58851 | E21: 1.3796573 | F21: 1499.1634 | I21: 1499.1634 | K21: 1499.1634 | L21: 5647.5631
A22: 2041 | C22: 876.06023 | D22: 130.55492 | E22: 1.4067505 | F22: 1499.1634 | I22: 1499.1634 | K22: 1499.1634 | L22: 5505.5122
A23: 2042 | D23: 145.55781 | E23: 1.4332925 | F23: 1499.1634 | I23: 1499.1634 | K23: 1499.1634 | L23: 4644.4814
A24: 2043 | D24: 96.331787 | E24: 1.4601432 | F24: 109.23368 | I24: 1499.1634 | K24: 1499.1634 | L24: 3205.3525
A25: 2044 | D25: 88.409765 | E25: 1.4863632 | F25: 235.95501 | I25: 282.72929 | K25: 1499.1634 | L25: 2107.7439
A26: 2045 | D26: 83.339671 | E26: 1.7877845 | F26: 1184.0104 | I26: 1499.1634 | K26: 1499.1634 | L26: 4267.4647
A27: 2046 | D27: 80.487743 | E27: 1.5122182 | F27: 1499.1634 | I27: 1499.1634 | K27: 1499.1634 | L27: 4579.4903
A28: 2047 | C28: 993.10467 | D28: 80.487743 | E28: 1.3255808 | F28: 1499.1634 | G28: 971.87689 | I28: 1499.1634 | J28: 73.54732 | K28: 1499.1634 | L28: 6617.8325
A29: 2048 | C29: 993.10467 | D29: 40.243872 | E29: 1.7889575 | F29: 1499.1634 | I29: 1499.1634 | J29: 156.93566 | K29: 1499.1634 | L29: 5689.5635
A30: 2049 | D30: 40.243872 | E30: 1.4235105 | I30: 1129.4675 | K30: 1499.1634 | L30: 2670.2983
A31: 2050 | D31: 40.243872 | L31: 40.243872
A32: 2051 | D32: 40.243872 | K32: 1499.1634 | L32: 1539.4073
A33: 2052 | D33: 40.243872 | F33: 1499.1634 | I33: 370.96297 | K33: 1499.1634 | L33: 3409.5337
A34: 2053 | D34: 40.243872 | E34: 0.69920361 | F34: 1426.682 | I34: 709.4495 | K34: 1499.1634 | L34: 3676.238
A35: 2054 | D35: 40.243872 | E35: 0.71428273 | F35: 329.40127 | I35: 670.87524 | K35: 1499.1634 | L35: 2540.3981
A36: 2055 | D36: 40.243872 | K36: 362.48493 | L36: 402.7288
A37: Grand Total | B37: 1199.0772 | C37: 3855.3742 | D37: 7133.4149 | E37: 44.814424 | F37: 19822.478 | G37: 971.87689 | H37: 384.82642 | I37: 19301.745 | J37: 230.48298 | K37: 31843.949 | L37: 84788.039

Sheet EmploymentAggregated
A1: raw_lookup_key | B1: scenario | C1: region | D1: technology | E1: year | F1: variable_name | G1: employment_variable | H1: factor_type | I1: job_type | J1: capacity_pj_per_year | K1: capacity_mw | L1: employment_fte
A2: =B2&"|"&F2&"|"&C2&"|"&D2&"|"&E2 -> CN|NewCapacity|RE1|PWRHYDDAM|2028 | B2: CN | C2: RE1 | D2: PWRHYDDAM | E2: 2028 | F2: NewCapacity | G2: EmploymentConstructionManufacturingDirect | H2: Construction&Manufacturing | I2: Direct | J2: =SUMIFS(RawResultsLong!$P:$P,RawResultsLong!$A:$A,A2) -> 37.84 | K2: =J2*1000/31.5576 -> 1199.0772 | L2: =SUMIFS(EmploymentResults!$V:$V,EmploymentResults!$D:$D,B2,EmploymentResults!$F:$F,C2,EmploymentResults!$G:$G,D2,EmploymentResults!$H:$H,E2,EmploymentResults!$J:$J,G2,EmploymentResults!$K:$K,H2,EmploymentResults!$L:$L,I2) -> 13862.852
A3: =B3&"|"&F3&"|"&C3&"|"&D3&"|"&E3 -> CN|NewCapacity|RE1|PWRHYDROR_NDC|2040 | B3: CN | C3: RE1 | D3: PWRHYDROR_NDC | E3: 2040 | F3: NewCapacity | G3: EmploymentConstructionManufacturingDirect | H3: Construction&Manufacturing | I3: Direct | J3: =SUMIFS(RawResultsLong!$P:$P,RawResultsLong!$A:$A,A3) -> 31.34 | K3: =J3*1000/31.5576 -> 993.10467 | L3: =SUMIFS(EmploymentResults!$V:$V,EmploymentResults!$D:$D,B3,EmploymentResults!$F:$F,C3,EmploymentResults!$G:$G,D3,EmploymentResults!$H:$H,E3,EmploymentResults!$J:$J,G3,EmploymentResults!$K:$K,H3,EmploymentResults!$L:$L,I3) -> 28299.81
A4: =B4&"|"&F4&"|"&C4&"|"&D4&"|"&E4 -> CN|NewCapacity|RE1|PWRHYDROR_NDC|2041 | B4: CN | C4: RE1 | D4: PWRHYDROR_NDC | E4: 2041 | F4: NewCapacity | G4: EmploymentConstructionManufacturingDirect | H4: Construction&Manufacturing | I4: Direct | J4: =SUMIFS(RawResultsLong!$P:$P,RawResultsLong!$A:$A,A4) -> 27.646358 | K4: =J4*1000/31.5576 -> 876.06023 | L4: =SUMIFS(EmploymentResults!$V:$V,EmploymentResults!$D:$D,B4,EmploymentResults!$F:$F,C4,EmploymentResults!$G:$G,D4,EmploymentResults!$H:$H,E4,EmploymentResults!$J:$J,G4,EmploymentResults!$K:$K,H4,EmploymentResults!$L:$L,I4) -> 24958.108
A5: =B5&"|"&F5&"|"&C5&"|"&D5&"|"&E5 -> CN|NewCapacity|RE1|PWRHYDROR_NDC|2047 | B5: CN | C5: RE1 | D5: PWRHYDROR_NDC | E5: 2047 | F5: NewCapacity | G5: EmploymentConstructionManufacturingDirect | H5: Construction&Manufacturing | I5: Direct | J5: =SUMIFS(RawResultsLong!$P:$P,RawResultsLong!$A:$A,A5) -> 31.34 | K5: =J5*1000/31.5576 -> 993.10467 | L5: =SUMIFS(EmploymentResults!$V:$V,EmploymentResults!$D:$D,B5,EmploymentResults!$F:$F,C5,EmploymentResults!$G:$G,D5,EmploymentResults!$H:$H,E5,EmploymentResults!$J:$J,G5,EmploymentResults!$K:$K,H5,EmploymentResults!$L:$L,I5) -> 28249.272
A6: =B6&"|"&F6&"|"&C6&"|"&D6&"|"&E6 -> CN|NewCapacity|RE1|PWRHYDROR_NDC|2048 | B6: CN | C6: RE1 | D6: PWRHYDROR_NDC | E6: 2048 | F6: NewCapacity | G6: EmploymentConstructionManufacturingDirect | H6: Construction&Manufacturing | I6: Direct | J6: =SUMIFS(RawResultsLong!$P:$P,RawResultsLong!$A:$A,A6) -> 31.34 | K6: =J6*1000/31.5576 -> 993.10467 | L6: =SUMIFS(EmploymentResults!$V:$V,EmploymentResults!$D:$D,B6,EmploymentResults!$F:$F,C6,EmploymentResults!$G:$G,D6,EmploymentResults!$H:$H,E6,EmploymentResults!$J:$J,G6,EmploymentResults!$K:$K,H6,EmploymentResults!$L:$L,I6) -> 28242.053
A7: =B7&"|"&F7&"|"&C7&"|"&D7&"|"&E7 -> CN|NewCapacity|RE1|PWRSOLRTP|2026 | B7: CN | C7: RE1 | D7: PWRSOLRTP | E7: 2026 | F7: NewCapacity | G7: EmploymentConstructionManufacturingDirect | H7: Construction&Manufacturing | I7: Direct | J7: =SUMIFS(RawResultsLong!$P:$P,RawResultsLong!$A:$A,A7) -> 10.37 | K7: =J7*1000/31.5576 -> 328.60547 | L7: =SUMIFS(EmploymentResults!$V:$V,EmploymentResults!$D:$D,B7,EmploymentResults!$F:$F,C7,EmploymentResults!$G:$G,D7,EmploymentResults!$H:$H,E7,EmploymentResults!$J:$J,G7,EmploymentResults!$K:$K,H7,EmploymentResults!$L:$L,I7) -> 2748.2612
A8: =B8&"|"&F8&"|"&C8&"|"&D8&"|"&E8 -> CN|NewCapacity|RE1|PWRSOLRTP|2027 | B8: CN | C8: RE1 | D8: PWRSOLRTP | E8: 2027 | F8: NewCapacity | G8: EmploymentConstructionManufacturingDirect | H8: Construction&Manufacturing | I8: Direct | J8: =SUMIFS(RawResultsLong!$P:$P,RawResultsLong!$A:$A,A8) -> 14.84 | K8: =J8*1000/31.5576 -> 470.25122 | L8: =SUMIFS(EmploymentResults!$V:$V,EmploymentResults!$D:$D,B8,EmploymentResults!$F:$F,C8,EmploymentResults!$G:$G,D8,EmploymentResults!$H:$H,E8,EmploymentResults!$J:$J,G8,EmploymentResults!$K:$K,H8,EmploymentResults!$L:$L,I8) -> 3706.1016
A9: =B9&"|"&F9&"|"&C9&"|"&D9&"|"&E9 -> CN|NewCapacity|RE1|PWRSOLRTP|2028 | B9: CN | C9: RE1 | D9: PWRSOLRTP | E9: 2028 | F9: NewCapacity | G9: EmploymentConstructionManufacturingDirect | H9: Construction&Manufacturing | I9: Direct | J9: =SUMIFS(RawResultsLong!$P:$P,RawResultsLong!$A:$A,A9) -> 16.33 | K9: =J9*1000/31.5576 -> 517.46647 | L9: =SUMIFS(EmploymentResults!$V:$V,EmploymentResults!$D:$D,B9,EmploymentResults!$F:$F,C9,EmploymentResults!$G:$G,D9,EmploymentResults!$H:$H,E9,EmploymentResults!$J:$J,G9,EmploymentResults!$K:$K,H9,EmploymentResults!$L:$L,I9) -> 3828.6379
A10: =B10&"|"&F10&"|"&C10&"|"&D10&"|"&E10 -> CN|NewCapacity|RE1|PWRSOLRTP|2029 | B10: CN | C10: RE1 | D10: PWRSOLRTP | E10: 2029 | F10: NewCapacity | G10: EmploymentConstructionManufacturingDirect | H10: Construction&Manufacturing | I10: Direct | J10: =SUMIFS(RawResultsLong!$P:$P,RawResultsLong!$A:$A,A10) -> 17.82 | K10: =J10*1000/31.5576 -> 564.68172 | L10: =SUMIFS(EmploymentResults!$V:$V,EmploymentResults!$D:$D,B10,EmploymentResults!$F:$F,C10,EmploymentResults!$G:$G,D10,EmploymentResults!$H:$H,E10,EmploymentResults!$J:$J,G10,EmploymentResults!$K:$K,H10,EmploymentResults!$L:$L,I10) -> 3905.6306
A11: =B11&"|"&F11&"|"&C11&"|"&D11&"|"&E11 -> CN|NewCapacity|RE1|PWRSOLRTP|2030 | B11: CN | C11: RE1 | D11: PWRSOLRTP | E11: 2030 | F11: NewCapacity | G11: EmploymentConstructionManufacturingDirect | H11: Construction&Manufacturing | I11: Direct | J11: =SUMIFS(RawResultsLong!$P:$P,RawResultsLong!$A:$A,A11) -> 18.1 | K11: =J11*1000/31.5576 -> 573.55439 | L11: =SUMIFS(EmploymentResults!$V:$V,EmploymentResults!$D:$D,B11,EmploymentResults!$F:$F,C11,EmploymentResults!$G:$G,D11,EmploymentResults!$H:$H,E11,EmploymentResults!$J:$J,G11,EmploymentResults!$K:$K,H11,EmploymentResults!$L:$L,I11) -> 3690.3752
A12: =B12&"|"&F12&"|"&C12&"|"&D12&"|"&E12 -> CN|NewCapacity|RE1|PWRSOLRTP|2031 | B12: CN | C12: RE1 | D12: PWRSOLRTP | E12: 2031 | F12: NewCapacity | G12: EmploymentConstructionManufacturingDirect | H12: Construction&Manufacturing | I12: Direct | J12: =SUMIFS(RawResultsLong!$P:$P,RawResultsLong!$A:$A,A12) -> 17.63 | K12: =J12*1000/31.5576 -> 558.66099 | L12: =SUMIFS(EmploymentResults!$V:$V,EmploymentResults!$D:$D,B12,EmploymentResults!$F:$F,C12,EmploymentResults!$G:$G,D12,EmploymentResults!$H:$H,E12,EmploymentResults!$J:$J,G12,EmploymentResults!$K:$K,H12,EmploymentResults!$L:$L,I12) -> 3535.5068
A13: =B13&"|"&F13&"|"&C13&"|"&D13&"|"&E13 -> CN|NewCapacity|RE1|PWRSOLRTP|2032 | B13: CN | C13: RE1 | D13: PWRSOLRTP | E13: 2032 | F13: NewCapacity | G13: EmploymentConstructionManufacturingDirect | H13: Construction&Manufacturing | I13: Direct | J13: =SUMIFS(RawResultsLong!$P:$P,RawResultsLong!$A:$A,A13) -> 15.79 | K13: =J13*1000/31.5576 -> 500.35491 | L13: =SUMIFS(EmploymentResults!$V:$V,EmploymentResults!$D:$D,B13,EmploymentResults!$F:$F,C13,EmploymentResults!$G:$G,D13,EmploymentResults!$H:$H,E13,EmploymentResults!$J:$J,G13,EmploymentResults!$K:$K,H13,EmploymentResults!$L:$L,I13) -> 3113.6356
... A878: =B878&"|"&F878&"|"&C878&"|"&D878&"|"&E878 -> PD|AccumulatedNewCapacity|RE1|PWRWNDONS|2055 | B878: PD | C878: RE1 | D878: PWRWNDONS | E878: 2055 | F878: AccumulatedNewCapacity | G878: EmploymentOMDirect | H878: O&M | I878: Direct | J878: =SUMIFS(RawResultsLong!$P:$P,RawResultsLong!$A:$A,A878) -> 621.59432 | K878: =J878*1000/31.5576 -> 19697.135 | L878: =SUMIFS(EmploymentResults!$V:$V,EmploymentResults!$D:$D,B878,EmploymentResults!$F:$F,C878,EmploymentResults!$G:$G,D878,EmploymentResults!$H:$H,E878,EmploymentResults!$J:$J,G878,EmploymentResults!$K:$K,H878,EmploymentResults!$L:$L,I878) -> 530.52868

Sheet EmploymentResults
A1: raw_lookup_key | B1: factor_lookup_key | C1: mapping_lookup_key | D1: scenario | E1: source_file | F1: region | G1: technology | H1: year | I1: variable_name | J1: employment_variable | K1: factor_type | L1: job_type | M1: value_pj_per_year | N1: capacity_mw | O1: employment_technology | P1: component_multiplier | Q1: component_capacity_mw | R1: factor_value | S1: factor_unit | T1: factor_source | U1: default_source | V1: employment_fte | W1: mapping_note
A2: =D2&"|"&I2&"|"&F2&"|"&G2&"|"&H2 -> PD|AccumulatedNewCapacity|RE1|PWRSOLUGE|2025 | B2: =O2&"|"&H2&"|"&K2&"|"&L2 -> Utility-scale solar PV|2025|O&M|Direct | C2: =G2&"|"&O2 -> PWRSOLUGE|Utility-scale solar PV | D2: PD | E2: simulation_328_results_filtered_PD.xlsx | F2: RE1 | G2: PWRSOLUGE | H2: 2025 | I2: AccumulatedNewCapacity | J2: EmploymentOMDirect | K2: O&M | L2: Direct | M2: =SUMIFS(RawResultsLong!$P:$P,RawResultsLong!$A:$A,A2) -> 6.717168 | N2: =M2*1000/31.5576 -> 212.85421 | O2: Utility-scale solar PV | P2: =SUMIFS(TechnologyMapping!$D:$D,TechnologyMapping!$A:$A,C2) -> 1 | Q2: =N2*P2 -> 212.85421 | R2: =SUMIFS(FactorInputs!$I:$I,FactorInputs!$A:$A,B2) -> 0.094109234 | S2: =_xlfn.XLOOKUP(B2,FactorInputs!$A$2:$A$888,FactorInputs!$F$2:$F$888,"") -> job/MW | T2: =_xlfn.XLOOKUP(B2,FactorInputs!$A$2:$A$888,FactorInputs!$B$2:$B$888,"") -> I-JEDI | U2: =_xlfn.XLOOKUP(B2,FactorInputs!$A$2:$A$888,FactorInputs!$T$2:$T$888,"") -> I-JEDI | V2: =Q2*R2 -> 20.031547
A3: =D3&"|"&I3&"|"&F3&"|"&G3&"|"&H3 -> PD|AccumulatedNewCapacity|RE1|PWRSOLUPE|2025 | B3: =O3&"|"&H3&"|"&K3&"|"&L3 -> Utility-scale solar PV|2025|O&M|Direct | C3: =G3&"|"&O3 -> PWRSOLUPE|Utility-scale solar PV | D3: PD | E3: simulation_328_results_filtered_PD.xlsx | F3: RE1 | G3: PWRSOLUPE | H3: 2025 | I3: AccumulatedNewCapacity | J3: EmploymentOMDirect | K3: O&M | L3: Direct | M3: =SUMIFS(RawResultsLong!$P:$P,RawResultsLong!$A:$A,A3) -> 5.3106624 | N3: =M3*1000/31.5576 -> 168.28474 | O3: Utility-scale solar PV | P3: =SUMIFS(TechnologyMapping!$D:$D,TechnologyMapping!$A:$A,C3) -> 1 | Q3: =N3*P3 -> 168.28474 | R3: =SUMIFS(FactorInputs!$I:$I,FactorInputs!$A:$A,B3) -> 0.094109234 | S3: =_xlfn.XLOOKUP(B3,FactorInputs!$A$2:$A$888,FactorInputs!$F$2:$F$888,"") -> job/MW | T3: =_xlfn.XLOOKUP(B3,FactorInputs!$A$2:$A$888,FactorInputs!$B$2:$B$888,"") -> I-JEDI | U3: =_xlfn.XLOOKUP(B3,FactorInputs!$A$2:$A$888,FactorInputs!$T$2:$T$888,"") -> I-JEDI | V3: =Q3*R3 -> 15.837148 | W3: Small-scale solar parks mapped to the available utility-scale solar PV factor.
A4: =D4&"|"&I4&"|"&F4&"|"&G4&"|"&H4 -> PD|AccumulatedNewCapacity|RE1|PWRWNDONS|2025 | B4: =O4&"|"&H4&"|"&K4&"|"&L4 -> Onshore wind|2025|O&M|Direct | C4: =G4&"|"&O4 -> PWRWNDONS|Onshore wind | D4: PD | E4: simulation_328_results_filtered_PD.xlsx | F4: RE1 | G4: PWRWNDONS | H4: 2025 | I4: AccumulatedNewCapacity | J4: EmploymentOMDirect | K4: O&M | L4: Direct | M4: =SUMIFS(RawResultsLong!$P:$P,RawResultsLong!$A:$A,A4) -> 0.15362331 | N4: =M4*1000/31.5576 -> 4.8680291 | O4: Onshore wind | P4: =SUMIFS(TechnologyMapping!$D:$D,TechnologyMapping!$A:$A,C4) -> 1 | Q4: =N4*P4 -> 4.8680291 | R4: =SUMIFS(FactorInputs!$I:$I,FactorInputs!$A:$A,B4) -> 0.029744526 | S4: =_xlfn.XLOOKUP(B4,FactorInputs!$A$2:$A$888,FactorInputs!$F$2:$F$888,"") -> job/MW | T4: =_xlfn.XLOOKUP(B4,FactorInputs!$A$2:$A$888,FactorInputs!$B$2:$B$888,"") -> I-JEDI | U4: =_xlfn.XLOOKUP(B4,FactorInputs!$A$2:$A$888,FactorInputs!$T$2:$T$888,"") -> I-JEDI | V4: =Q4*R4 -> 0.14479722
A5: =D5&"|"&I5&"|"&F5&"|"&G5&"|"&H5 -> PD|NewCapacity|RE1|PWRSOLUGE|2025 | B5: =O5&"|"&H5&"|"&K5&"|"&L5 -> Utility-scale solar PV|2025|Construction&Manufacturing|Direct | C5: =G5&"|"&O5 -> PWRSOLUGE|Utility-scale solar PV | D5: PD | E5: simulation_328_results_filtered_PD.xlsx | F5: RE1 | G5: PWRSOLUGE | H5: 2025 | I5: NewCapacity | J5: EmploymentConstructionManufacturingDirect | K5: Construction&Manufacturing | L5: Direct | M5: =SUMIFS(RawResultsLong!$P:$P,RawResultsLong!$A:$A,A5) -> 6.717168 | N5: =M5*1000/31.5576 -> 212.85421 | O5: Utility-scale solar PV | P5: =SUMIFS(TechnologyMapping!$D:$D,TechnologyMapping!$A:$A,C5) -> 1 | Q5: =N5*P5 -> 212.85421 | R5: =SUMIFS(FactorInputs!$I:$I,FactorInputs!$A:$A,B5) -> 9.4551514 | S5: =_xlfn.XLOOKUP(B5,FactorInputs!$A$2:$A$888,FactorInputs!$F$2:$F$888,"") -> job-yr/MW | T5: =_xlfn.XLOOKUP(B5,FactorInputs!$A$2:$A$888,FactorInputs!$B$2:$B$888,"") -> I-JEDI | U5: =_xlfn.XLOOKUP(B5,FactorInputs!$A$2:$A$888,FactorInputs!$T$2:$T$888,"") -> I-JEDI | V5: =Q5*R5 -> 2012.5688
A6: =D6&"|"&I6&"|"&F6&"|"&G6&"|"&H6 -> PD|NewCapacity|RE1|PWRSOLUPE|2025 | B6: =O6&"|"&H6&"|"&K6&"|"&L6 -> Utility-scale solar PV|2025|Construction&Manufacturing|Direct | C6: =G6&"|"&O6 -> PWRSOLUPE|Utility-scale solar PV | D6: PD | E6: simulation_328_results_filtered_PD.xlsx | F6: RE1 | G6: PWRSOLUPE | H6: 2025 | I6: NewCapacity | J6: EmploymentConstructionManufacturingDirect | K6: Construction&Manufacturing | L6: Direct | M6: =SUMIFS(RawResultsLong!$P:$P,RawResultsLong!$A:$A,A6) -> 5.3106624 | N6: =M6*1000/31.5576 -> 168.28474 | O6: Utility-scale solar PV | P6: =SUMIFS(TechnologyMapping!$D:$D,TechnologyMapping!$A:$A,C6) -> 1 | Q6: =N6*P6 -> 168.28474 | R6: =SUMIFS(FactorInputs!$I:$I,FactorInputs!$A:$A,B6) -> 9.4551514 | S6: =_xlfn.XLOOKUP(B6,FactorInputs!$A$2:$A$888,FactorInputs!$F$2:$F$888,"") -> job-yr/MW | T6: =_xlfn.XLOOKUP(B6,FactorInputs!$A$2:$A$888,FactorInputs!$B$2:$B$888,"") -> I-JEDI | U6: =_xlfn.XLOOKUP(B6,FactorInputs!$A$2:$A$888,FactorInputs!$T$2:$T$888,"") -> I-JEDI | V6: =Q6*R6 -> 1591.1577 | W6: Small-scale solar parks mapped to the available utility-scale solar PV factor.
A7: =D7&"|"&I7&"|"&F7&"|"&G7&"|"&H7 -> PD|NewCapacity|RE1|PWRWNDONS|2025 | B7: =O7&"|"&H7&"|"&K7&"|"&L7 -> Onshore wind|2025|Construction&Manufacturing|Direct | C7: =G7&"|"&O7 -> PWRWNDONS|Onshore wind | D7: PD | E7: simulation_328_results_filtered_PD.xlsx | F7: RE1 | G7: PWRWNDONS | H7: 2025 | I7: NewCapacity | J7: EmploymentConstructionManufacturingDirect | K7: Construction&Manufacturing | L7: Direct | M7: =SUMIFS(RawResultsLong!$P:$P,RawResultsLong!$A:$A,A7) -> 0.15362331 | N7: =M7*1000/31.5576 -> 4.8680291 | O7: Onshore wind | P7: =SUMIFS(TechnologyMapping!$D:$D,TechnologyMapping!$A:$A,C7) -> 1 | Q7: =N7*P7 -> 4.8680291 | R7: =SUMIFS(FactorInputs!$I:$I,FactorInputs!$A:$A,B7) -> 7.1854325 | S7: =_xlfn.XLOOKUP(B7,FactorInputs!$A$2:$A$888,FactorInputs!$F$2:$F$888,"") -> job-yr/MW | T7: =_xlfn.XLOOKUP(B7,FactorInputs!$A$2:$A$888,FactorInputs!$B$2:$B$888,"") -> I-JEDI | U7: =_xlfn.XLOOKUP(B7,FactorInputs!$A$2:$A$888,FactorInputs!$T$2:$T$888,"") -> I-JEDI | V7: =Q7*R7 -> 34.978894
A8: =D8&"|"&I8&"|"&F8&"|"&G8&"|"&H8 -> PD|AccumulatedNewCapacity|RE1|PWRSOLRTP|2026 | B8: =O8&"|"&H8&"|"&K8&"|"&L8 -> Rooftop solar PV|2026|O&M|Direct | C8: =G8&"|"&O8 -> PWRSOLRTP|Rooftop solar PV | D8: PD | E8: simulation_328_results_filtered_PD.xlsx | F8: RE1 | G8: PWRSOLRTP | H8: 2026 | I8: AccumulatedNewCapacity | J8: EmploymentOMDirect | K8: O&M | L8: Direct | M8: =SUMIFS(RawResultsLong!$P:$P,RawResultsLong!$A:$A,A8) -> 7.9387888 | N8: =M8*1000/31.5576 -> 251.56504 | O8: Rooftop solar PV | P8: =SUMIFS(TechnologyMapping!$D:$D,TechnologyMapping!$A:$A,C8) -> 1 | Q8: =N8*P8 -> 251.56504 | R8: =SUMIFS(FactorInputs!$I:$I,FactorInputs!$A:$A,B8) -> 0.28588235 | S8: =_xlfn.XLOOKUP(B8,FactorInputs!$A$2:$A$888,FactorInputs!$F$2:$F$888,"") -> job/MW | T8: =_xlfn.XLOOKUP(B8,FactorInputs!$A$2:$A$888,FactorInputs!$B$2:$B$888,"") -> JEDI-US | U8: =_xlfn.XLOOKUP(B8,FactorInputs!$A$2:$A$888,FactorInputs!$T$2:$T$888,"") -> JEDI-US | V8: =Q8*R8 -> 71.918005
A9: =D9&"|"&I9&"|"&F9&"|"&G9&"|"&H9 -> PD|AccumulatedNewCapacity|RE1|PWRSOLUGE|2026 | B9: =O9&"|"&H9&"|"&K9&"|"&L9 -> Utility-scale solar PV|2026|O&M|Direct | C9: =G9&"|"&O9 -> PWRSOLUGE|Utility-scale solar PV | D9: PD | E9: simulation_328_results_filtered_PD.xlsx | F9: RE1 | G9: PWRSOLUGE | H9: 2026 | I9: AccumulatedNewCapacity | J9: EmploymentOMDirect | K9: O&M | L9: Direct | M9: =SUMIFS(RawResultsLong!$P:$P,RawResultsLong!$A:$A,A9) -> 62.504352 | N9: =M9*1000/31.5576 -> 1980.6434 | O9: Utility-scale solar PV | P9: =SUMIFS(TechnologyMapping!$D:$D,TechnologyMapping!$A:$A,C9) -> 1 | Q9: =N9*P9 -> 1980.6434 | R9: =SUMIFS(FactorInputs!$I:$I,FactorInputs!$A:$A,B9) -> 0.091718468 | S9: =_xlfn.XLOOKUP(B9,FactorInputs!$A$2:$A$888,FactorInputs!$F$2:$F$888,"") -> job/MW | T9: =_xlfn.XLOOKUP(B9,FactorInputs!$A$2:$A$888,FactorInputs!$B$2:$B$888,"") -> I-JEDI | U9: =_xlfn.XLOOKUP(B9,FactorInputs!$A$2:$A$888,FactorInputs!$T$2:$T$888,"") -> I-JEDI | V9: =Q9*R9 -> 181.66158
A10: =D10&"|"&I10&"|"&F10&"|"&G10&"|"&H10 -> PD|AccumulatedNewCapacity|RE1|PWRSOLUPE|2026 | B10: =O10&"|"&H10&"|"&K10&"|"&L10 -> Utility-scale solar PV|2026|O&M|Direct | C10: =G10&"|"&O10 -> PWRSOLUPE|Utility-scale solar PV | D10: PD | E10: simulation_328_results_filtered_PD.xlsx | F10: RE1 | G10: PWRSOLUPE | H10: 2026 | I10: AccumulatedNewCapacity | J10: EmploymentOMDirect | K10: O&M | L10: Direct | M10: =SUMIFS(RawResultsLong!$P:$P,RawResultsLong!$A:$A,A10) -> 8.6752382 | N10: =M10*1000/31.5576 -> 274.90171 | O10: Utility-scale solar PV | P10: =SUMIFS(TechnologyMapping!$D:$D,TechnologyMapping!$A:$A,C10) -> 1 | Q10: =N10*P10 -> 274.90171 | R10: =SUMIFS(FactorInputs!$I:$I,FactorInputs!$A:$A,B10) -> 0.091718468 | S10: =_xlfn.XLOOKUP(B10,FactorInputs!$A$2:$A$888,FactorInputs!$F$2:$F$888,"") -> job/MW | T10: =_xlfn.XLOOKUP(B10,FactorInputs!$A$2:$A$888,FactorInputs!$B$2:$B$888,"") -> I-JEDI | U10: =_xlfn.XLOOKUP(B10,FactorInputs!$A$2:$A$888,FactorInputs!$T$2:$T$888,"") -> I-JEDI | V10: =Q10*R10 -> 25.213564 | W10: Small-scale solar parks mapped to the available utility-scale solar PV factor.
A11: =D11&"|"&I11&"|"&F11&"|"&G11&"|"&H11 -> PD|AccumulatedNewCapacity|RE1|PWRWNDONS|2026 | B11: =O11&"|"&H11&"|"&K11&"|"&L11 -> Onshore wind|2026|O&M|Direct | C11: =G11&"|"&O11 -> PWRWNDONS|Onshore wind | D11: PD | E11: simulation_328_results_filtered_PD.xlsx | F11: RE1 | G11: PWRWNDONS | H11: 2026 | I11: AccumulatedNewCapacity | J11: EmploymentOMDirect | K11: O&M | L11: Direct | M11: =SUMIFS(RawResultsLong!$P:$P,RawResultsLong!$A:$A,A11) -> 0.15362331 | N11: =M11*1000/31.5576 -> 4.8680291 | O11: Onshore wind | P11: =SUMIFS(TechnologyMapping!$D:$D,TechnologyMapping!$A:$A,C11) -> 1 | Q11: =N11*P11 -> 4.8680291 | R11: =SUMIFS(FactorInputs!$I:$I,FactorInputs!$A:$A,B11) -> 0.029489051 | S11: =_xlfn.XLOOKUP(B11,FactorInputs!$A$2:$A$888,FactorInputs!$F$2:$F$888,"") -> job/MW | T11: =_xlfn.XLOOKUP(B11,FactorInputs!$A$2:$A$888,FactorInputs!$B$2:$B$888,"") -> I-JEDI | U11: =_xlfn.XLOOKUP(B11,FactorInputs!$A$2:$A$888,FactorInputs!$T$2:$T$888,"") -> I-JEDI | V11: =Q11*R11 -> 0.14355356
A12: =D12&"|"&I12&"|"&F12&"|"&G12&"|"&H12 -> PD|NewCapacity|RE1|PWRSOLRTP|2026 | B12: =O12&"|"&H12&"|"&K12&"|"&L12 -> Rooftop solar PV|2026|Construction&Manufacturing|Direct | C12: =G12&"|"&O12 -> PWRSOLRTP|Rooftop solar PV | D12: PD | E12: simulation_328_results_filtered_PD.xlsx | F12: RE1 | G12: PWRSOLRTP | H12: 2026 | I12: NewCapacity | J12: EmploymentConstructionManufacturingDirect | K12: Construction&Manufacturing | L12: Direct | M12: =SUMIFS(RawResultsLong!$P:$P,RawResultsLong!$A:$A,A12) -> 7.9387888 | N12: =M12*1000/31.5576 -> 251.56504 | O12: Rooftop solar PV | P12: =SUMIFS(TechnologyMapping!$D:$D,TechnologyMapping!$A:$A,C12) -> 1 | Q12: =N12*P12 -> 251.56504 | R12: =SUMIFS(FactorInputs!$I:$I,FactorInputs!$A:$A,B12) -> 8.3634067 | S12: =_xlfn.XLOOKUP(B12,FactorInputs!$A$2:$A$888,FactorInputs!$F$2:$F$888,"") -> job-yr/MW | T12: =_xlfn.XLOOKUP(B12,FactorInputs!$A$2:$A$888,FactorInputs!$B$2:$B$888,"") -> JEDI-US | U12: =_xlfn.XLOOKUP(B12,FactorInputs!$A$2:$A$888,FactorInputs!$T$2:$T$888,"") -> JEDI-US | V12: =Q12*R12 -> 2103.9407
A13: =D13&"|"&I13&"|"&F13&"|"&G13&"|"&H13 -> PD|NewCapacity|RE1|PWRSOLUGE|2026 | B13: =O13&"|"&H13&"|"&K13&"|"&L13 -> Utility-scale solar PV|2026|Construction&Manufacturing|Direct | C13: =G13&"|"&O13 -> PWRSOLUGE|Utility-scale solar PV | D13: PD | E13: simulation_328_results_filtered_PD.xlsx | F13: RE1 | G13: PWRSOLUGE | H13: 2026 | I13: NewCapacity | J13: EmploymentConstructionManufacturingDirect | K13: Construction&Manufacturing | L13: Direct | M13: =SUMIFS(RawResultsLong!$P:$P,RawResultsLong!$A:$A,A13) -> 55.787184 | N13: =M13*1000/31.5576 -> 1767.7892 | O13: Utility-scale solar PV | P13: =SUMIFS(TechnologyMapping!$D:$D,TechnologyMapping!$A:$A,C13) -> 1 | Q13: =N13*P13 -> 1767.7892 | R13: =SUMIFS(FactorInputs!$I:$I,FactorInputs!$A:$A,B13) -> 8.9403029 | S13: =_xlfn.XLOOKUP(B13,FactorInputs!$A$2:$A$888,FactorInputs!$F$2:$F$888,"") -> job-yr/MW | T13: =_xlfn.XLOOKUP(B13,FactorInputs!$A$2:$A$888,FactorInputs!$B$2:$B$888,"") -> I-JEDI | U13: =_xlfn.XLOOKUP(B13,FactorInputs!$A$2:$A$888,FactorInputs!$T$2:$T$888,"") -> I-JEDI | V13: =Q13*R13 -> 15804.571
A14: =D14&"|"&I14&"|"&F14&"|"&G14&"|"&H14 -> PD|NewCapacity|RE1|PWRSOLUPE|2026 | B14: =O14&"|"&H14&"|"&K14&"|"&L14 -> Utility-scale solar PV|2026|Construction&Manufacturing|Direct | C14: =G14&"|"&O14 -> PWRSOLUPE|Utility-scale solar PV | D14: PD | E14: simulation_328_results_filtered_PD.xlsx | F14: RE1 | G14: PWRSOLUPE | H14: 2026 | I14: NewCapacity | J14: EmploymentConstructionManufacturingDirect | K14: Construction&Manufacturing | L14: Direct | M14: =SUMIFS(RawResultsLong!$P:$P,RawResultsLong!$A:$A,A14) -> 3.3645758 | N14: =M14*1000/31.5576 -> 106.61697 | O14: Utility-scale solar PV | P14: =SUMIFS(TechnologyMapping!$D:$D,TechnologyMapping!$A:$A,C14) -> 1 | Q14: =N14*P14 -> 106.61697 | R14: =SUMIFS(FactorInputs!$I:$I,FactorInputs!$A:$A,B14) -> 8.9403029 | S14: =_xlfn.XLOOKUP(B14,FactorInputs!$A$2:$A$888,FactorInputs!$F$2:$F$888,"") -> job-yr/MW | T14: =_xlfn.XLOOKUP(B14,FactorInputs!$A$2:$A$888,FactorInputs!$B$2:$B$888,"") -> I-JEDI | U14: =_xlfn.XLOOKUP(B14,FactorInputs!$A$2:$A$888,FactorInputs!$T$2:$T$888,"") -> I-JEDI | V14: =Q14*R14 -> 953.18804 | W14: Small-scale solar parks mapped to the available utility-scale solar PV factor.
A15: =D15&"|"&I15&"|"&F15&"|"&G15&"|"&H15 -> PD|AccumulatedNewCapacity|RE1|PWRSOLRTP|2027 | B15: =O15&"|"&H15&"|"&K15&"|"&L15 -> Rooftop solar PV|2027|O&M|Direct | C15: =G15&"|"&O15 -> PWRSOLRTP|Rooftop solar PV | D15: PD | E15: simulation_328_results_filtered_PD.xlsx | F15: RE1 | G15: PWRSOLRTP | H15: 2027 | I15: AccumulatedNewCapacity | J15: EmploymentOMDirect | K15: O&M | L15: Direct | M15: =SUMIFS(RawResultsLong!$P:$P,RawResultsLong!$A:$A,A15) -> 18.718751 | N15: =M15*1000/31.5576 -> 593.16142 | O15: Rooftop solar PV | P15: =SUMIFS(TechnologyMapping!$D:$D,TechnologyMapping!$A:$A,C15) -> 1 | Q15: =N15*P15 -> 593.16142 | R15: =SUMIFS(FactorInputs!$I:$I,FactorInputs!$A:$A,B15) -> 0.27882353 | S15: =_xlfn.XLOOKUP(B15,FactorInputs!$A$2:$A$888,FactorInputs!$F$2:$F$888,"") -> job/MW | T15: =_xlfn.XLOOKUP(B15,FactorInputs!$A$2:$A$888,FactorInputs!$B$2:$B$888,"") -> JEDI-US | U15: =_xlfn.XLOOKUP(B15,FactorInputs!$A$2:$A$888,FactorInputs!$T$2:$T$888,"") -> JEDI-US | V15: =Q15*R15 -> 165.38736
A16: =D16&"|"&I16&"|"&F16&"|"&G16&"|"&H16 -> PD|AccumulatedNewCapacity|RE1|PWRSOLUGE|2027 | B16: =O16&"|"&H16&"|"&K16&"|"&L16 -> Utility-scale solar PV|2027|O&M|Direct | C16: =G16&"|"&O16 -> PWRSOLUGE|Utility-scale solar PV | D16: PD | E16: simulation_328_results_filtered_PD.xlsx | F16: RE1 | G16: PWRSOLUGE | H16: 2027 | I16: AccumulatedNewCapacity | J16: EmploymentOMDirect | K16: O&M | L16: Direct | M16: =SUMIFS(RawResultsLong!$P:$P,RawResultsLong!$A:$A,A16) -> 135.51019 | N16: =M16*1000/31.5576 -> 4294.0589 | O16: Utility-scale solar PV | P16: =SUMIFS(TechnologyMapping!$D:$D,TechnologyMapping!$A:$A,C16) -> 1 | Q16: =N16*P16 -> 4294.0589 | R16: =SUMIFS(FactorInputs!$I:$I,FactorInputs!$A:$A,B16) -> 0.089327703 | S16: =_xlfn.XLOOKUP(B16,FactorInputs!$A$2:$A$888,FactorInputs!$F$2:$F$888,"") -> job/MW | T16: =_xlfn.XLOOKUP(B16,FactorInputs!$A$2:$A$888,FactorInputs!$B$2:$B$888,"") -> I-JEDI | U16: =_xlfn.XLOOKUP(B16,FactorInputs!$A$2:$A$888,FactorInputs!$T$2:$T$888,"") -> I-JEDI | V16: =Q16*R16 -> 383.57841
A17: =D17&"|"&I17&"|"&F17&"|"&G17&"|"&H17 -> PD|AccumulatedNewCapacity|RE1|PWRSOLUPE|2027 | B17: =O17&"|"&H17&"|"&K17&"|"&L17 -> Utility-scale solar PV|2027|O&M|Direct | C17: =G17&"|"&O17 -> PWRSOLUPE|Utility-scale solar PV | D17: PD | E17: simulation_328_results_filtered_PD.xlsx | F17: RE1 | G17: PWRSOLUPE | H17: 2027 | I17: AccumulatedNewCapacity | J17: EmploymentOMDirect | K17: O&M | L17: Direct | M17: =SUMIFS(RawResultsLong!$P:$P,RawResultsLong!$A:$A,A17) -> 12.144198 | N17: =M17*1000/31.5576 -> 384.82642 | O17: Utility-scale solar PV | P17: =SUMIFS(TechnologyMapping!$D:$D,TechnologyMapping!$A:$A,C17) -> 1 | Q17: =N17*P17 -> 384.82642 | R17: =SUMIFS(FactorInputs!$I:$I,FactorInputs!$A:$A,B17) -> 0.089327703 | S17: =_xlfn.XLOOKUP(B17,FactorInputs!$A$2:$A$888,FactorInputs!$F$2:$F$888,"") -> job/MW | T17: =_xlfn.XLOOKUP(B17,FactorInputs!$A$2:$A$888,FactorInputs!$B$2:$B$888,"") -> I-JEDI | U17: =_xlfn.XLOOKUP(B17,FactorInputs!$A$2:$A$888,FactorInputs!$T$2:$T$888,"") -> I-JEDI | V17: =Q17*R17 -> 34.37566 | W17: Small-scale solar parks mapped to the available utility-scale solar PV factor.
A18: =D18&"|"&I18&"|"&F18&"|"&G18&"|"&H18 -> PD|AccumulatedNewCapacity|RE1|PWRWNDONS|2027 | B18: =O18&"|"&H18&"|"&K18&"|"&L18 -> Onshore wind|2027|O&M|Direct | C18: =G18&"|"&O18 -> PWRWNDONS|Onshore wind | D18: PD | E18: simulation_328_results_filtered_PD.xlsx | F18: RE1 | G18: PWRWNDONS | H18: 2027 | I18: AccumulatedNewCapacity | J18: EmploymentOMDirect | K18: O&M | L18: Direct | M18: =SUMIFS(RawResultsLong!$P:$P,RawResultsLong!$A:$A,A18) -> 17.466887 | N18: =M18*1000/31.5576 -> 553.49226 | O18: Onshore wind | P18: =SUMIFS(TechnologyMapping!$D:$D,TechnologyMapping!$A:$A,C18) -> 1 | Q18: =N18*P18 -> 553.49226 | R18: =SUMIFS(FactorInputs!$I:$I,FactorInputs!$A:$A,B18) -> 0.029233577 | S18: =_xlfn.XLOOKUP(B18,FactorInputs!$A$2:$A$888,FactorInputs!$F$2:$F$888,"") -> job/MW | T18: =_xlfn.XLOOKUP(B18,FactorInputs!$A$2:$A$888,FactorInputs!$B$2:$B$888,"") -> I-JEDI | U18: =_xlfn.XLOOKUP(B18,FactorInputs!$A$2:$A$888,FactorInputs!$T$2:$T$888,"") -> I-JEDI | V18: =Q18*R18 -> 16.180558
